Workbook

Sheet Information
A1: SELECTED HOUSING CHARACTERISTICS
A3: Note: The table shown may have been modified by user selections. Some information may be missing.
A5: DATA NOTES
A6: TABLE ID: | B6: DP04
A7: SURVEY/PROGRAM: | B7: American Community Survey
A8: VINTAGE: | B8: 2020
A9: DATASET: | B9: ACSDP5Y2020
A10: PRODUCT: | B10: ACS 5-Year Estimates Data Profiles
A11: UNIVERSE: | B11: None
A12: MLA: | B12: U.S. Census Bureau. "SELECTED HOUSING CHARACTERISTICS." American Community Survey, ACS 5-Year Estimates Data Profiles, Table DP04, https://data.census.gov/table/ACSDP5Y2020.DP04?q=financial+characteristics+2020&g=160XX00US0541000,1235000,4748000_310XX00US47260_3810000US440005_3910000US47492048000. Accessed on 23 Apr 2026.
A13: FTP URL: | B13: None
A14: API URL: | B14: https://api.census.gov/data/2020/acs/acs5/profile
A16: USER SELECTIONS
A17: TOPICS | B17: Financial Characteristics
A18: VINTAGES | B18: 2020
A19: GEOS | B19: Virginia Beach-Chesapeake-Norfolk, VA-NC Metro Area; Memphis city, Tennessee; Memphis city; Memphis, TN--AR--MS MSA (part); Tennessee; Arkansas (part); Little Rock--North Little Rock, AR MSA; Jacksonville city, Florida; Little Rock city, Arkansas
A21: EXCLUDED COLUMNS | B21: None
A23: APPLIED FILTERS | B23: None
A25: APPLIED SORTS | B25: None
A27: PIVOT & GROUPING
A28: PIVOT COLUMNS | B28: None
A29: PIVOT MODE | B29: Off
A30: ROW GROUPS | B30: None
A31: VALUE COLUMNS | B31: None
A33: WEB ADDRESS | B33: https://data.census.gov/table/ACSDP5Y2020.DP04?q=financial+characteristics+2020&g=160XX00US0541000,1235000,4748000_310XX00US47260_3810000US440005_3910000US47492048000
A35: TABLE NOTES
B36: Although the American Community Survey (ACS) produces population, demographic and housing unit estimates, for 2020, the 2020 Census provides the official counts of the population and housing units for the nation, states, counties, cities, and towns. For 2016 to 2019, the Population Estimates Program provides estimates of the population for the nation, states, counties, cities, and towns and intercensal housing unit estimates for the nation, states, and counties.
B37: Supporting documentation on code lists, subject definitions, data accuracy, and statistical testing can be found on the American Community Survey website in the Technical Documentation section. Sample size and data quality measures (including coverage rates, allocation rates, and response rates) can be found on the American Community Survey website in the Methodology section.
B38: Source: U.S. Census Bureau, 2016-2020 American Community Survey 5-Year Estimates
B39: Data are based on a sample and are subject to sampling variability. The degree of uncertainty for an estimate arising from sampling variability is represented through the use of a margin of error. The value shown here is the 90 percent margin of error. The margin of error can be interpreted roughly as providing a 90 percent probability that the interval defined by the estimate minus the margin of error and the estimate plus the margin of error (the lower and upper confidence bounds) contains the true value. In addition to sampling variability, the ACS estimates are subject to nonsampling error (for a discussion of nonsampling variability, see ACS Technical Documentation). The effect of nonsampling error is not represented in these tables.
B40: Households not paying cash rent are excluded from the calculation of median gross rent.
B41: Telephone service data are not available for certain geographic areas due to problems with data collection of this question that occurred in 2016 and 2019. Both ACS 1-year and ACS 5-year files were affected. It may take several years in the ACS 5-year files until the estimates are available for the geographic areas affected.
B42: The 2016-2020 American Community Survey (ACS) data generally reflect the September 2018 Office of Management and Budget (OMB) delineations of metropolitan and micropolitan statistical areas. In certain instances, the names, codes, and boundaries of the principal cities shown in ACS tables may differ from the OMB delineation lists due to differences in the effective dates of the geographic entities.
B43: Estimates of urban and rural populations, housing units, and characteristics reflect boundaries of urban areas defined based on Census 2010 data. As a result, data for urban and rural areas from the ACS do not necessarily reflect the results of ongoing urbanization.
B44: Explanation of Symbols:- The estimate could not be computed because there were an insufficient number of sample observations. For a ratio of medians estimate, one or both of the median estimates falls in the lowest interval or highest interval of an open-ended distribution.N The estimate or margin of error cannot be displayed because there were an insufficient number of sample cases in the selected geographic area. (X) The estimate or margin of error is not applicable or not available.median- The median falls in the lowest interval of an open-ended distribution (for example "2,500-")median+ The median falls in the highest interval of an open-ended distribution (for example "250,000+").** The margin of error could not be computed because there were an insufficient number of sample observations.*** The margin of error could not be computed because the median falls in the lowest interval or highest interval of an open-ended distribution.***** A margin of error is not appropriate because the corresponding estimate is controlled to an independent population or housing estimate. Effectively, the corresponding estimate has no sampling error and the margin of error may be treated as zero.
A46: COLUMN NOTES | B46: None

Sheet Table
B3: Norfolk | G3: Memphis
C4: 2020 | D4: 2024 | E4: CAGR | H4: 2020 | I4: 2024 | J4: CAGR
B5: Population | C5: =VALUE(SUBSTITUTE('Population (2020)'!E2,",","")) -> 1799674 | D5: =VALUE(SUBSTITUTE('Population (2024)'!N4,",","")) -> 1796689 | E5: =_xlfn.RRI(4,C5,D5) -> -0.00041491659 | G5: Population | H5: =VALUE(SUBSTITUTE('Population (2020)'!D2,",","")) -> 633104 | I5: =VALUE(SUBSTITUTE('Population (2024)'!J4,",","")) -> 610936 | J5: =_xlfn.RRI(4,H5,I5) -> -0.0088710426
B6: Housing Units | C6: =VALUE(SUBSTITUTE('Data (2020)'!N4,",","")) -> 739434 | D6: =VALUE(SUBSTITUTE('Data (2024)'!N4,",","")) -> 774453 | E6: =_xlfn.RRI(4,C6,D6) -> 0.011635154 | G6: Housing Units | H6: =VALUE(SUBSTITUTE('Data (2020)'!J4,",","")) -> 299599 | I6: =VALUE(SUBSTITUTE('Data (2024)'!J4,",","")) -> 291759 | J6: =_xlfn.RRI(4,H6,I6) -> -0.006607274
B7: Median Income | C7: =VALUE(SUBSTITUTE('Income (2020)'!AL17,",","")) -> 68454 | D7: =VALUE(SUBSTITUTE('Income (2024)'!AL17,",","")) -> 82402 | E7: =_xlfn.RRI(4,C7,D7) -> 0.047453448 | G7: Median Income | H7: =VALUE(SUBSTITUTE('Income (2020)'!Z17,",","")) -> 41864 | I7: =VALUE(SUBSTITUTE('Income (2024)'!Z17,",","")) -> 52679 | J7: =_xlfn.RRI(4,H7,I7) -> 0.05912983
B8: Adjusted Median Income | C8: =C7/'CPI Fred Data'!D22 -> 82968.813 | D8: =D7/'CPI Fred Data'!D26 -> 82402 | E8: =_xlfn.RRI(4,C8,D8) -> -0.001712304 | G8: Adjusted Median Income | H8: =H7/'CPI Fred Data'!D22 -> 50740.737 | I8: =I7/'CPI Fred Data'!D26 -> 52679 | J8: =_xlfn.RRI(4,H8,I8) -> 0.0094160085
B9: Av House Hold Size | C9: =VALUE('Data (2020)'!N56) -> 2.6 | D9: =VALUE('Data (2024)'!N56) -> 2.56 | E9: =_xlfn.RRI(4,C9,D9) -> -0.0038685445 | G9: Av House Hold Size | H9: =VALUE('Data (2020)'!J56) -> 2.53 | I9: =VALUE('Data (2024)'!J56) -> 2.44 | J9: =_xlfn.RRI(4,H9,I9) -> -0.00901444
B10: Owner Occupied HU | C10: =VALUE(SUBSTITUTE('Data (2020)'!N54,",","")) -> 418960 | D10: =VALUE(SUBSTITUTE('Data (2024)'!N54,",","")) -> 451287 | E10: =_xlfn.RRI(4,C10,D10) -> 0.018755733 | G10: Owner Occupied HU | H10: =VALUE(SUBSTITUTE('Data (2020)'!J54,",","")) -> 118235 | I10: =VALUE(SUBSTITUTE('Data (2024)'!J54,",","")) -> 111737 | J10: =_xlfn.RRI(4,H10,I10) -> -0.014032187
B11: Renter HU | C11: =VALUE(SUBSTITUTE('Data (2020)'!N55,",","")) -> 253093 | D11: =VALUE(SUBSTITUTE('Data (2024)'!N55,",","")) -> 266624 | E11: =_xlfn.RRI(4,C11,D11) -> 0.013105741 | G11: Renter HU | H11: =VALUE(SUBSTITUTE('Data (2020)'!J55,",","")) -> 137521 | I11: =VALUE(SUBSTITUTE('Data (2024)'!J55,",","")) -> 139093 | J11: =_xlfn.RRI(4,H11,I11) -> 0.0028455763
B12: Vacancy Rate | C12: =VALUE('Data (2020)'!N8)/100 -> 0.068 | D12: =VALUE('Data (2024)'!N8)/100 -> 0.053 | E12: =D12-C12 -> -0.015 | F12: actual change value | G12: Vacancy Rate | H12: =VALUE('Data (2020)'!J8)/100 -> 0.083 | I12: =VALUE('Data (2024)'!J8)/100 -> 0.101 | J12: =I12-H12 -> 0.018 | K12: actual change value
B13: Median Rent | C13: =VALUE(SUBSTITUTE('Data (2020)'!N152,",","")) -> 1187 | D13: =VALUE(SUBSTITUTE('Data (2024)'!N152,",","")) -> 1556 | E13: =_xlfn.RRI(4,C13,D13) -> 0.070014637 | G13: Median Rent | H13: =VALUE(SUBSTITUTE('Data (2020)'!J152,",","")) -> 915 | I13: =VALUE(SUBSTITUTE('Data (2024)'!J152,",","")) -> 1263 | J13: =_xlfn.RRI(4,H13,I13) -> 0.083915843
B14: Adjusted Median Rent | C14: =C13/'CPI Fred Data'!D22 -> 1438.6885 | D14: =D13/'CPI Fred Data'!D26 -> 1556 | E14: =_xlfn.RRI(4,C14,D14) -> 0.0197899 | G14: Adjusted Median Rent | H14: =H13/'CPI Fred Data'!D22 -> 1109.0143 | I14: =I13/'CPI Fred Data'!D26 -> 1263 | J14: =_xlfn.RRI(4,H14,I14) -> 0.033038606
B15: Median Home Value | C15: =VALUE(SUBSTITUTE('Data (2020)'!N103,",","")) -> 253800 | D15: =VALUE(SUBSTITUTE('Data (2024)'!N103,",","")) -> 363400 | E15: =_xlfn.RRI(4,C15,D15) -> 0.093889179 | G15: Median Home Value | H15: =VALUE(SUBSTITUTE('Data (2020)'!J103,",","")) -> 107100 | I15: =VALUE(SUBSTITUTE('Data (2024)'!J103,",","")) -> 209800 | J15: =_xlfn.RRI(4,H15,I15) -> 0.18305246
B16: Adjusted Median Home Value | C16: =C15/'CPI Fred Data'!D22 -> 307615.11 | D16: =D15/'CPI Fred Data'!D26 -> 363400 | E16: =_xlfn.RRI(4,C16,D16) -> 0.04254381 | G16: Adjusted Median Home Value | H16: =H15/'CPI Fred Data'!D22 -> 129809.21 | I16: =I15/'CPI Fred Data'!D26 -> 209800 | J16: =_xlfn.RRI(4,H16,I16) -> 0.12752191
B18: Jacksonville FL | G18: Little Rock
C19: 2020 | D19: 2024 | E19: CAGR | H19: 2020 | I19: 2024 | J19: CAGR
B20: Population | C20: =VALUE(SUBSTITUTE('Population (2020)'!C2,",","")) -> 949611 | D20: =VALUE(SUBSTITUTE('Population (2024)'!F4,",","")) -> 1009831 | E20: =_xlfn.RRI(4,C20,D20) -> 0.015490209 | G20: Population | H20: =VALUE(SUBSTITUTE('Population (2020)'!B2,",","")) -> 202591 | I20: =VALUE(SUBSTITUTE('Population (2024)'!B4,",","")) -> 204793 | J20: =_xlfn.RRI(4,H20,I20) -> 0.0027062916
B21: Housing Units | C21: =VALUE(SUBSTITUTE('Data (2020)'!F4,",","")) -> 389130 | D21: =VALUE(SUBSTITUTE('Data (2024)'!F4,",","")) -> 449941 | E21: =_xlfn.RRI(4,C21,D21) -> 0.036967664 | G21: Housing Units | H21: =VALUE(SUBSTITUTE('Data (2020)'!B4,",","")) -> 96399 | I21: =VALUE(SUBSTITUTE('Data (2024)'!B4,",","")) -> 99014 | J21: =_xlfn.RRI(4,H21,I21) -> 0.0067137937
B22: Median Income | C22: =VALUE(SUBSTITUTE('Income (2020)'!N17,",","")) -> 55531 | D22: =VALUE(SUBSTITUTE('Income (2024)'!N17,",","")) -> 72389 | E22: =_xlfn.RRI(4,C22,D22) -> 0.068523974 | G22: Median Income | H22: =VALUE(SUBSTITUTE('Income (2020)'!B17,",","")) -> 53620 | I22: =VALUE(SUBSTITUTE('Income (2024)'!B17,",","")) -> 66553 | J22: =_xlfn.RRI(4,H22,I22) -> 0.055504786
B23: Adjusted Median Income | C23: =C22/'CPI Fred Data'!D22 -> 67305.653 | D23: =D22/'CPI Fred Data'!D26 -> 72389 | E23: =_xlfn.RRI(4,C23,D23) -> 0.018369206 | G23: Adjusted Median Income | H23: =H22/'CPI Fred Data'!D22 -> 64989.449 | I23: =I22/'CPI Fred Data'!D26 -> 66553 | J23: =_xlfn.RRI(4,H23,I23) -> 0.0059611176
B24: Av House Hold Size | C24: =VALUE('Data (2020)'!F56) -> 2.62 | D24: =VALUE('Data (2024)'!F56) -> 2.56 | E24: =_xlfn.RRI(4,C24,D24) -> -0.0057750249 | G24: Av House Hold Size | H24: =VALUE('Data (2020)'!B56) -> 2.45 | I24: =VALUE('Data (2024)'!B56) -> 2.43 | J24: =_xlfn.RRI(4,H24,I24) -> -0.0020470936
B25: Owner Occupied HU | C25: =VALUE(SUBSTITUTE('Data (2020)'!F54,",","")) -> 196649 | D25: =VALUE(SUBSTITUTE('Data (2024)'!F54,",","")) -> 240209 | E25: =_xlfn.RRI(4,C25,D25) -> 0.051294478 | G25: Owner Occupied HU | H25: =VALUE(SUBSTITUTE('Data (2020)'!B54,",","")) -> 45625 | I25: =VALUE(SUBSTITUTE('Data (2024)'!B54,",","")) -> 47340 | J25: =_xlfn.RRI(4,H25,I25) -> 0.009267629
B26: Renter HU | C26: =VALUE(SUBSTITUTE('Data (2020)'!F55,",","")) -> 152160 | D26: =VALUE(SUBSTITUTE('Data (2024)'!F55,",","")) -> 173411 | E26: =_xlfn.RRI(4,C26,D26) -> 0.03322293 | G26: Renter HU | H26: =VALUE(SUBSTITUTE('Data (2020)'!B55,",","")) -> 37900 | I26: =VALUE(SUBSTITUTE('Data (2024)'!B55,",","")) -> 41398 | J26: =_xlfn.RRI(4,H26,I26) -> 0.022315717
B27: Vacancy Rate | C27: =VALUE('Data (2020)'!F8)/100 -> 0.066 | D27: =VALUE('Data (2024)'!F8)/100 -> 0.111 | E27: =D27-C27 -> 0.045 | F27: actual change value | G27: Vacancy Rate | H27: =VALUE('Data (2020)'!B8)/100 -> 0.12 | I27: =VALUE('Data (2024)'!B8)/100 -> 0.073 | J27: =I27-H27 -> -0.047 | K27: actual change value
B28: Median Rent | C28: =VALUE(SUBSTITUTE('Data (2020)'!F152,",","")) -> 1089 | D28: =VALUE(SUBSTITUTE('Data (2024)'!F152,",","")) -> 1568 | E28: =_xlfn.RRI(4,C28,D28) -> 0.095417172 | G28: Median Rent | H28: =VALUE(SUBSTITUTE('Data (2020)'!B152,",","")) -> 889 | I28: =VALUE(SUBSTITUTE('Data (2024)'!B152,",","")) -> 1136 | J28: =_xlfn.RRI(4,H28,I28) -> 0.06321022
B29: Adjusted Median Rent | C29: =C28/'CPI Fred Data'!D22 -> 1319.9088 | D29: =D28/'CPI Fred Data'!D26 -> 1568 | E29: =_xlfn.RRI(4,C29,D29) -> 0.044000081 | G29: Adjusted Median Rent | H29: =H28/'CPI Fred Data'!D22 -> 1077.5013 | I29: =I28/'CPI Fred Data'!D26 -> 1136 | J29: =_xlfn.RRI(4,H29,I29) -> 0.013304871
B30: Median Home Value | C30: =VALUE(SUBSTITUTE('Data (2020)'!F103,",","")) -> 187700 | D30: =VALUE(SUBSTITUTE('Data (2024)'!F103,",","")) -> 325300 | E30: =_xlfn.RRI(4,C30,D30) -> 0.14737385 | G30: Median Home Value | H30: =VALUE(SUBSTITUTE('Data (2020)'!B103,",","")) -> 172500 | I30: =VALUE(SUBSTITUTE('Data (2024)'!B103,",","")) -> 270700 | J30: =_xlfn.RRI(4,H30,I30) -> 0.11924404
B31: Adjusted Median Home Value | C31: =C30/'CPI Fred Data'!D22 -> 227499.43 | D31: =D30/'CPI Fred Data'!D26 -> 325300 | E31: =_xlfn.RRI(4,C31,D31) -> 0.093517998 | G31: Adjusted Median Home Value | H31: =H30/'CPI Fred Data'!D22 -> 209076.46 | I31: =I30/'CPI Fred Data'!D26 -> 270700 | J31: =_xlfn.RRI(4,H31,I31) -> 0.066708552

Sheet Income (2024)
B1: Little Rock city, Arkansas | N1: Jacksonville city, Florida | Z1: Memphis city, Tennessee | AL1: Virginia Beach-Chesapeake-Norfolk, VA-NC Metro Area
B2: Occupied housing units | D2: Percent occupied housing units | F2: Owner-occupied housing units | H2: Percent owner-occupied housing units | J2: Renter-occupied housing units | L2: Percent renter-occupied housing units | N2: Occupied housing units | P2: Percent occupied housing units | R2: Owner-occupied housing units | T2: Percent owner-occupied housing units | V2: Renter-occupied housing units | X2: Percent renter-occupied housing units | Z2: Occupied housing units | AB2: Percent occupied housing units | AD2: Owner-occupied housing units | AF2: Percent owner-occupied housing units | AH2: Renter-occupied housing units | AJ2: Percent renter-occupied housing units | AL2: Occupied housing units | AN2: Percent occupied housing units | AP2: Owner-occupied housing units | AR2: Percent owner-occupied housing units | AT2: Renter-occupied housing units | AV2: Percent renter-occupied housing units
A3: Label | B3: Estimate | C3: Margin of Error | D3: Estimate | E3: Margin of Error | F3: Estimate | G3: Margin of Error | H3: Estimate | I3: Margin of Error | J3: Estimate | K3: Margin of Error | L3: Estimate | M3: Margin of Error | N3: Estimate | O3: Margin of Error | P3: Estimate | Q3: Margin of Error | R3: Estimate | S3: Margin of Error | T3: Estimate | U3: Margin of Error | V3: Estimate | W3: Margin of Error | X3: Estimate | Y3: Margin of Error | Z3: Estimate | AA3: Margin of Error | AB3: Estimate | AC3: Margin of Error | AD3: Estimate | AE3: Margin of Error | AF3: Estimate | AG3: Margin of Error | AH3: Estimate | AI3: Margin of Error | AJ3: Estimate | AK3: Margin of Error | AL3: Estimate | AM3: Margin of Error | AN3: Estimate | AO3: Margin of Error | AP3: Estimate | AQ3: Margin of Error | AR3: Estimate | AS3: Margin of Error | AT3: Estimate | AU3: Margin of Error | AV3: Estimate | AW3: Margin of Error
A4: Occupied housing units | B4: 88,738 | C4: ±3,214 | D4: 88,738 | E4: ±3,214 | F4: 47,340 | G4: ±3,245 | H4: 47,340 | I4: ±3,245 | J4: 41,398 | K4: ±3,265 | L4: 41,398 | M4: ±3,265 | N4: 413,620 | O4: ±4,742 | P4: 413,620 | Q4: ±4,742 | R4: 240,209 | S4: ±6,346 | T4: 240,209 | U4: ±6,346 | V4: 173,411 | W4: ±7,223 | X4: 173,411 | Y4: ±7,223 | Z4: 250,830 | AA4: ±4,397 | AB4: 250,830 | AC4: ±4,397 | AD4: 111,737 | AE4: ±4,092 | AF4: 111,737 | AG4: ±4,092 | AH4: 139,093 | AI4: ±4,742 | AJ4: 139,093 | AK4: ±4,742 | AL4: 717,911 | AM4: ±5,455 | AN4: 717,911 | AO4: ±5,455 | AP4: 451,287 | AQ4: ±7,983 | AR4: 451,287 | AS4: ±7,983 | AT4: 266,624 | AU4: ±7,499 | AV4: 266,624 | AW4: ±7,499
A5: HOUSEHOLD INCOME IN THE PAST 12 MONTHS (IN 2024 INFLATION-ADJUSTED DOLLARS)
A6: Less than $5,000 | B6: 4,349 | C6: ±1,383 | D6: 4.9% | E6: ±1.5 | F6: 1,467 | G6: ±686 | H6: 3.1% | I6: ±1.4 | J6: 2,882 | K6: ±1,240 | L6: 7.0% | M6: ±2.9 | N6: 16,855 | O6: ±2,901 | P6: 4.1% | Q6: ±0.7 | R6: 6,668 | S6: ±1,753 | T6: 2.8% | U6: ±0.7 | V6: 10,187 | W6: ±2,196 | X6: 5.9% | Y6: ±1.3 | Z6: 17,912 | AA6: ±3,113 | AB6: 7.1% | AC6: ±1.2 | AD6: 6,346 | AE6: ±1,716 | AF6: 5.7% | AG6: ±1.5 | AH6: 11,566 | AI6: ±2,511 | AJ6: 8.3% | AK6: ±1.8 | AL6: 20,599 | AM6: ±2,324 | AN6: 2.9% | AO6: ±0.3 | AP6: 8,022 | AQ6: ±1,431 | AR6: 1.8% | AS6: ±0.3 | AT6: 12,577 | AU6: ±1,980 | AV6: 4.7% | AW6: ±0.8
A7: $5,000 to $9,999 | B7: 1,385 | C7: ±752 | D7: 1.6% | E7: ±0.8 | F7: 708 | G7: ±460 | H7: 1.5% | I7: ±0.9 | J7: 677 | K7: ±562 | L7: 1.6% | M7: ±1.4 | N7: 8,321 | O7: ±2,128 | P7: 2.0% | Q7: ±0.5 | R7: 2,695 | S7: ±871 | T7: 1.1% | U7: ±0.4 | V7: 5,626 | W7: ±1,851 | X7: 3.2% | Y7: ±1.1 | Z7: 8,135 | AA7: ±1,951 | AB7: 3.2% | AC7: ±0.8 | AD7: 2,245 | AE7: ±1,100 | AF7: 2.0% | AG7: ±1.0 | AH7: 5,890 | AI7: ±1,713 | AJ7: 4.2% | AK7: ±1.2 | AL7: 11,354 | AM7: ±2,116 | AN7: 1.6% | AO7: ±0.3 | AP7: 4,037 | AQ7: ±1,059 | AR7: 0.9% | AS7: ±0.2 | AT7: 7,317 | AU7: ±1,674 | AV7: 2.7% | AW7: ±0.6
A8: $10,000 to $14,999 | B8: 2,499 | C8: ±1,040 | D8: 2.8% | E8: ±1.2 | F8: 698 | G8: ±398 | H8: 1.5% | I8: ±0.8 | J8: 1,801 | K8: ±925 | L8: 4.4% | M8: ±2.3 | N8: 11,420 | O8: ±2,211 | P8: 2.8% | Q8: ±0.5 | R8: 5,264 | S8: ±1,246 | T8: 2.2% | U8: ±0.5 | V8: 6,156 | W8: ±1,701 | X8: 3.5% | Y8: ±1.0 | Z8: 13,299 | AA8: ±2,789 | AB8: 5.3% | AC8: ±1.1 | AD8: 3,167 | AE8: ±1,052 | AF8: 2.8% | AG8: ±0.9 | AH8: 10,132 | AI8: ±2,588 | AJ8: 7.3% | AK8: ±1.8 | AL8: 19,076 | AM8: ±2,688 | AN8: 2.7% | AO8: ±0.4 | AP8: 5,937 | AQ8: ±1,021 | AR8: 1.3% | AS8: ±0.2 | AT8: 13,139 | AU8: ±2,448 | AV8: 4.9% | AW8: ±0.9
A9: $15,000 to $19,999 | B9: 3,356 | C9: ±1,267 | D9: 3.8% | E9: ±1.4 | F9: 1,296 | G9: ±724 | H9: 2.7% | I9: ±1.5 | J9: 2,060 | K9: ±976 | L9: 5.0% | M9: ±2.3 | N9: 12,089 | O9: ±2,959 | P9: 2.9% | Q9: ±0.7 | R9: 5,100 | S9: ±1,684 | T9: 2.1% | U9: ±0.7 | V9: 6,989 | W9: ±2,156 | X9: 4.0% | Y9: ±1.2 | Z9: 10,184 | AA9: ±2,255 | AB9: 4.1% | AC9: ±0.9 | AD9: 3,159 | AE9: ±1,169 | AF9: 2.8% | AG9: ±1.1 | AH9: 7,025 | AI9: ±2,002 | AJ9: 5.1% | AK9: ±1.4 | AL9: 15,132 | AM9: ±2,667 | AN9: 2.1% | AO9: ±0.4 | AP9: 4,770 | AQ9: ±1,190 | AR9: 1.1% | AS9: ±0.3 | AT9: 10,362 | AU9: ±2,332 | AV9: 3.9% | AW9: ±0.8
A10: $20,000 to $24,999 | B10: 3,740 | C10: ±1,498 | D10: 4.2% | E10: ±1.7 | F10: 1,186 | G10: ±747 | H10: 2.5% | I10: ±1.6 | J10: 2,554 | K10: ±1,277 | L10: 6.2% | M10: ±3.1 | N10: 12,407 | O10: ±2,292 | P10: 3.0% | Q10: ±0.6 | R10: 4,379 | S10: ±1,185 | T10: 1.8% | U10: ±0.5 | V10: 8,028 | W10: ±2,028 | X10: 4.6% | Y10: ±1.1 | Z10: 14,833 | AA10: ±2,555 | AB10: 5.9% | AC10: ±1.0 | AD10: 4,704 | AE10: ±1,331 | AF10: 4.2% | AG10: ±1.2 | AH10: 10,129 | AI10: ±2,237 | AJ10: 7.3% | AK10: ±1.6 | AL10: 23,053 | AM10: ±2,749 | AN10: 3.2% | AO10: ±0.4 | AP10: 8,821 | AQ10: ±1,283 | AR10: 2.0% | AS10: ±0.3 | AT10: 14,232 | AU10: ±2,453 | AV10: 5.3% | AW10: ±0.9
A11: $25,000 to $34,999 | B11: 7,154 | C11: ±2,362 | D11: 8.1% | E11: ±2.6 | F11: 2,116 | G11: ±1,015 | H11: 4.5% | I11: ±2.1 | J11: 5,038 | K11: ±2,111 | L11: 12.2% | M11: ±4.9 | N11: 29,961 | O11: ±4,109 | P11: 7.2% | Q11: ±1.0 | R11: 11,875 | S11: ±2,001 | T11: 4.9% | U11: ±0.8 | V11: 18,086 | W11: ±3,716 | X11: 10.4% | Y11: ±2.1 | Z11: 19,796 | AA11: ±2,510 | AB11: 7.9% | AC11: ±1.0 | AD11: 6,651 | AE11: ±1,388 | AF11: 6.0% | AG11: ±1.2 | AH11: 13,145 | AI11: ±2,299 | AJ11: 9.5% | AK11: ±1.7 | AL11: 43,474 | AM11: ±4,288 | AN11: 6.1% | AO11: ±0.6 | AP11: 19,080 | AQ11: ±2,595 | AR11: 4.2% | AS11: ±0.6 | AT11: 24,394 | AU11: ±3,389 | AV11: 9.1% | AW11: ±1.3
A12: $35,000 to $49,999 | B12: 11,856 | C12: ±2,294 | D12: 13.4% | E12: ±2.6 | F12: 4,258 | G12: ±1,100 | H12: 9.0% | I12: ±2.2 | J12: 7,598 | K12: ±2,293 | L12: 18.4% | M12: ±5.2 | N12: 43,598 | O12: ±4,638 | P12: 10.5% | Q12: ±1.1 | R12: 18,001 | S12: ±2,372 | T12: 7.5% | U12: ±1.0 | V12: 25,597 | W12: ±3,947 | X12: 14.8% | Y12: ±2.2 | Z12: 34,536 | AA12: ±3,855 | AB12: 13.8% | AC12: ±1.5 | AD12: 12,436 | AE12: ±2,045 | AF12: 11.1% | AG12: ±1.8 | AH12: 22,100 | AI12: ±3,574 | AJ12: 15.9% | AK12: ±2.4 | AL12: 68,418 | AM12: ±4,890 | AN12: 9.5% | AO12: ±0.7 | AP12: 31,939 | AQ12: ±3,034 | AR12: 7.1% | AS12: ±0.6 | AT12: 36,479 | AU12: ±4,391 | AV12: 13.7% | AW12: ±1.6
A13: $50,000 to $74,999 | B13: 14,697 | C13: ±2,469 | D13: 16.6% | E13: ±2.7 | F13: 5,838 | G13: ±1,152 | H13: 12.3% | I13: ±2.4 | J13: 8,859 | K13: ±2,107 | L13: 21.4% | M13: ±4.9 | N13: 78,589 | O13: ±5,324 | P13: 19.0% | Q13: ±1.3 | R13: 40,871 | S13: ±3,412 | T13: 17.0% | U13: ±1.3 | V13: 37,718 | W13: ±4,464 | X13: 21.8% | Y13: ±2.5 | Z13: 44,673 | AA13: ±4,184 | AB13: 17.8% | AC13: ±1.6 | AD13: 19,767 | AE13: ±3,066 | AF13: 17.7% | AG13: ±2.6 | AH13: 24,906 | AI13: ±3,197 | AJ13: 17.9% | AK13: ±2.2 | AL13: 125,889 | AM13: ±6,290 | AN13: 17.5% | AO13: ±0.9 | AP13: 68,526 | AQ13: ±4,820 | AR13: 15.2% | AS13: ±1.0 | AT13: 57,363 | AU13: ±4,748 | AV13: 21.5% | AW13: ±1.6
A14: $75,000 to $99,999 | B14: 11,082 | C14: ±2,128 | D14: 12.5% | E14: ±2.3 | F14: 6,770 | G14: ±1,619 | H14: 14.3% | I14: ±3.2 | J14: 4,312 | K14: ±1,475 | L14: 10.4% | M14: ±3.5 | N14: 58,346 | O14: ±4,889 | P14: 14.1% | Q14: ±1.2 | R14: 32,490 | S14: ±3,695 | T14: 13.5% | U14: ±1.5 | V14: 25,856 | W14: ±4,197 | X14: 14.9% | Y14: ±2.3 | Z14: 31,172 | AA14: ±3,509 | AB14: 12.4% | AC14: ±1.4 | AD14: 14,666 | AE14: ±1,984 | AF14: 13.1% | AG14: ±1.7 | AH14: 16,506 | AI14: ±2,950 | AJ14: 11.9% | AK14: ±2.1 | AL14: 96,645 | AM14: ±4,961 | AN14: 13.5% | AO14: ±0.7 | AP14: 60,435 | AQ14: ±3,697 | AR14: 13.4% | AS14: ±0.8 | AT14: 36,210 | AU14: ±3,994 | AV14: 13.6% | AW14: ±1.4
A15: $100,000 to $149,999 | B15: 14,200 | C15: ±2,313 | D15: 16.0% | E15: ±2.6 | F15: 9,669 | G15: ±1,773 | H15: 20.4% | I15: ±3.5 | J15: 4,531 | K15: ±1,650 | L15: 10.9% | M15: ±3.9 | N15: 72,919 | O15: ±5,488 | P15: 17.6% | Q15: ±1.3 | R15: 55,515 | S15: ±4,560 | T15: 23.1% | U15: ±1.8 | V15: 17,404 | W15: ±3,065 | X15: 10.0% | Y15: ±1.7 | Z15: 30,426 | AA15: ±3,079 | AB15: 12.1% | AC15: ±1.2 | AD15: 17,086 | AE15: ±2,421 | AF15: 15.3% | AG15: ±2.1 | AH15: 13,340 | AI15: ±2,781 | AJ15: 9.6% | AK15: ±2.0 | AL15: 137,639 | AM15: ±5,284 | AN15: 19.2% | AO15: ±0.7 | AP15: 102,211 | AQ15: ±5,212 | AR15: 22.6% | AS15: ±1.0 | AT15: 35,428 | AU15: ±3,519 | AV15: 13.3% | AW15: ±1.3
A16: $150,000 or more | B16: 14,420 | C16: ±1,766 | D16: 16.3% | E16: ±2.0 | F16: 13,334 | G16: ±1,717 | H16: 28.2% | I16: ±3.5 | J16: 1,086 | K16: ±538 | L16: 2.6% | M16: ±1.3 | N16: 69,115 | O16: ±4,987 | P16: 16.7% | Q16: ±1.2 | R16: 57,351 | S16: ±4,756 | T16: 23.9% | U16: ±1.9 | V16: 11,764 | W16: ±2,777 | X16: 6.8% | Y16: ±1.6 | Z16: 25,864 | AA16: ±2,273 | AB16: 10.3% | AC16: ±0.9 | AD16: 21,510 | AE16: ±1,920 | AF16: 19.3% | AG16: ±1.7 | AH16: 4,354 | AI16: ±1,678 | AJ16: 3.1% | AK16: ±1.2 | AL16: 156,632 | AM16: ±5,841 | AN16: 21.8% | AO16: ±0.8 | AP16: 137,509 | AQ16: ±5,327 | AR16: 30.5% | AS16: ±1.1 | AT16: 19,123 | AU16: ±2,685 | AV16: 7.2% | AW16: ±1.0
A17: Median household income (dollars) | B17: 66,553 | C17: ±3,400 | D17: 66,553 | E17: ±3,400 | F17: 97,719 | G17: ±8,248 | H17: 97,719 | I17: ±8,248 | J17: 45,393 | K17: ±7,009 | L17: 45,393 | M17: ±7,009 | N17: 72,389 | O17: ±2,436 | P17: 72,389 | Q17: ±2,436 | R17: 92,720 | S17: ±4,096 | T17: 92,720 | U17: ±4,096 | V17: 53,641 | W17: ±3,880 | X17: 53,641 | Y17: ±3,880 | Z17: 52,679 | AA17: ±2,423 | AB17: 52,679 | AC17: ±2,423 | AD17: 71,480 | AE17: ±4,247 | AF17: 71,480 | AG17: ±4,247 | AH17: 41,982 | AI17: ±2,201 | AJ17: 41,982 | AK17: ±2,201 | AL17: 82,402 | AM17: ±1,660 | AN17: 82,402 | AO17: ±1,660 | AP17: 105,603 | AQ17: ±2,201 | AR17: 105,603 | AS17: ±2,201 | AT17: 54,460 | AU17: ±1,782 | AV17: 54,460 | AW17: ±1,782
A18: MONTHLY HOUSING COSTS
A19: Less than $300 | B19: 3,340 | C19: ±1,148 | D19: 3.8% | E19: ±1.3 | F19: 2,104 | G19: ±831 | H19: 4.4% | I19: ±1.7 | J19: 1,236 | K19: ±829 | L19: 3.0% | M19: ±2.0 | N19: 17,039 | O19: ±2,177 | P19: 4.1% | Q19: ±0.5 | R19: 13,520 | S19: ±1,827 | T19: 5.6% | U19: ±0.7 | V19: 3,519 | W19: ±1,116 | X19: 2.0% | Y19: ±0.7 | Z19: 7,960 | AA19: ±1,547 | AB19: 3.2% | AC19: ±0.6 | AD19: 5,681 | AE19: ±1,091 | AF19: 5.1% | AG19: ±1.0 | AH19: 2,279 | AI19: ±1,174 | AJ19: 1.6% | AK19: ±0.8 | AL19: 17,603 | AM19: ±2,256 | AN19: 2.5% | AO19: ±0.3 | AP19: 11,672 | AQ19: ±2,000 | AR19: 2.6% | AS19: ±0.4 | AT19: 5,931 | AU19: ±1,300 | AV19: 2.2% | AW19: ±0.5
A20: $300 to $499 | B20: 5,894 | C20: ±1,081 | D20: 6.6% | E20: ±1.2 | F20: 5,319 | G20: ±1,012 | H20: 11.2% | I20: ±2.2 | J20: 575 | K20: ±374 | L20: 1.4% | M20: ±0.9 | N20: 23,590 | O20: ±2,399 | P20: 5.7% | Q20: ±0.6 | R20: 19,397 | S20: ±2,052 | T20: 8.1% | U20: ±0.9 | V20: 4,193 | W20: ±1,333 | X20: 2.4% | Y20: ±0.8 | Z20: 18,968 | AA20: ±2,584 | AB20: 7.6% | AC20: ±1.0 | AD20: 15,963 | AE20: ±2,407 | AF20: 14.3% | AG20: ±2.1 | AH20: 3,005 | AI20: ±994 | AJ20: 2.2% | AK20: ±0.7 | AL20: 26,933 | AM20: ±2,630 | AN20: 3.8% | AO20: ±0.4 | AP20: 21,385 | AQ20: ±2,235 | AR20: 4.7% | AS20: ±0.5 | AT20: 5,548 | AU20: ±1,197 | AV20: 2.1% | AW20: ±0.4
A21: $500 to $799 | B21: 12,352 | C21: ±1,940 | D21: 13.9% | E21: ±2.0 | F21: 7,858 | G21: ±1,675 | H21: 16.6% | I21: ±3.1 | J21: 4,494 | K21: ±1,396 | L21: 10.9% | M21: ±3.2 | N21: 37,701 | O21: ±3,599 | P21: 9.1% | Q21: ±0.9 | R21: 30,049 | S21: ±3,196 | T21: 12.5% | U21: ±1.3 | V21: 7,652 | W21: ±2,232 | X21: 4.4% | Y21: ±1.3 | Z21: 31,830 | AA21: ±3,378 | AB21: 12.7% | AC21: ±1.3 | AD21: 19,435 | AE21: ±1,952 | AF21: 17.4% | AG21: ±1.8 | AH21: 12,395 | AI21: ±2,363 | AJ21: 8.9% | AK21: ±1.7 | AL21: 65,137 | AM21: ±4,526 | AN21: 9.1% | AO21: ±0.6 | AP21: 54,583 | AQ21: ±3,535 | AR21: 12.1% | AS21: ±0.7 | AT21: 10,554 | AU21: ±2,364 | AV21: 4.0% | AW21: ±0.9
A22: $800 to $999 | B22: 11,943 | C22: ±2,343 | D22: 13.5% | E22: ±2.5 | F22: 4,427 | G22: ±955 | H22: 9.4% | I22: ±2.0 | J22: 7,516 | K22: ±2,172 | L22: 18.2% | M22: ±4.9 | N22: 27,004 | O22: ±3,682 | P22: 6.5% | Q22: ±0.9 | R22: 17,681 | S22: ±2,828 | T22: 7.4% | U22: ±1.2 | V22: 9,323 | W22: ±2,231 | X22: 5.4% | Y22: ±1.3 | Z22: 28,950 | AA22: ±3,444 | AB22: 11.5% | AC22: ±1.4 | AD22: 11,710 | AE22: ±1,760 | AF22: 10.5% | AG22: ±1.6 | AH22: 17,240 | AI22: ±2,896 | AJ22: 12.4% | AK22: ±2.0 | AL22: 46,229 | AM22: ±3,441 | AN22: 6.4% | AO22: ±0.5 | AP22: 30,420 | AQ22: ±2,807 | AR22: 6.7% | AS22: ±0.6 | AT22: 15,809 | AU22: ±2,163 | AV22: 5.9% | AW22: ±0.8
A23: $1,000 to $1,499 | B23: 29,066 | C23: ±2,811 | D23: 32.8% | E23: ±3.0 | F23: 10,103 | G23: ±1,754 | H23: 21.3% | I23: ±3.2 | J23: 18,963 | K23: ±2,711 | L23: 45.8% | M23: ±5.5 | N23: 95,788 | O23: ±5,998 | P23: 23.2% | Q23: ±1.4 | R23: 44,181 | S23: ±3,948 | T23: 18.4% | U23: ±1.5 | V23: 51,607 | W23: ±5,272 | X23: 29.8% | Y23: ±3.0 | Z23: 84,972 | AA23: ±5,261 | AB23: 33.9% | AC23: ±1.9 | AD23: 24,168 | AE23: ±3,095 | AF23: 21.6% | AG23: ±2.6 | AH23: 60,804 | AI23: ±4,408 | AJ23: 43.7% | AK23: ±2.7 | AL23: 162,074 | AM23: ±7,481 | AN23: 22.6% | AO23: ±1.0 | AP23: 80,068 | AQ23: ±4,366 | AR23: 17.7% | AS23: ±0.9 | AT23: 82,006 | AU23: ±5,337 | AV23: 30.8% | AW23: ±1.8
A24: $1,500 to $1,999 | B24: 12,251 | C24: ±2,302 | D24: 13.8% | E24: ±2.5 | F24: 6,440 | G24: ±1,556 | H24: 13.6% | I24: ±3.2 | J24: 5,811 | K24: ±1,667 | L24: 14.0% | M24: ±3.8 | N24: 101,097 | O24: ±7,228 | P24: 24.4% | Q24: ±1.7 | R24: 41,618 | S24: ±3,856 | T24: 17.3% | U24: ±1.5 | V24: 59,479 | W24: ±5,807 | X24: 34.3% | Y24: ±2.9 | Z24: 40,825 | AA24: ±3,778 | AB24: 16.3% | AC24: ±1.5 | AD24: 13,355 | AE24: ±2,074 | AF24: 12.0% | AG24: ±1.8 | AH24: 27,470 | AI24: ±3,436 | AJ24: 19.7% | AK24: ±2.5 | AL24: 169,415 | AM24: ±7,141 | AN24: 23.6% | AO24: ±1.0 | AP24: 86,256 | AQ24: ±5,393 | AR24: 19.1% | AS24: ±1.1 | AT24: 83,159 | AU24: ±5,255 | AV24: 31.2% | AW24: ±1.6
A25: $2,000 to $2,499 | B25: 4,795 | C25: ±1,319 | D25: 5.4% | E25: ±1.5 | F25: 3,922 | G25: ±1,061 | H25: 8.3% | I25: ±2.1 | J25: 873 | K25: ±668 | L25: 2.1% | M25: ±1.6 | N25: 56,222 | O25: ±5,912 | P25: 13.6% | Q25: ±1.4 | R25: 31,719 | S25: ±4,189 | T25: 13.2% | U25: ±1.7 | V25: 24,503 | W25: ±4,152 | X25: 14.1% | Y25: ±2.2 | Z25: 14,190 | AA25: ±2,310 | AB25: 5.7% | AC25: ±0.9 | AD25: 8,364 | AE25: ±1,694 | AF25: 7.5% | AG25: ±1.5 | AH25: 5,826 | AI25: ±1,812 | AJ25: 4.2% | AK25: ±1.3 | AL25: 110,371 | AM25: ±6,409 | AN25: 15.4% | AO25: ±0.9 | AP25: 71,765 | AQ25: ±4,917 | AR25: 15.9% | AS25: ±1.0 | AT25: 38,606 | AU25: ±3,732 | AV25: 14.5% | AW25: ±1.4
A26: $2,500 to $2,999 | B26: 3,538 | C26: ±1,364 | D26: 4.0% | E26: ±1.6 | F26: 3,357 | G26: ±1,345 | H26: 7.1% | I26: ±2.9 | J26: 181 | K26: ±142 | L26: 0.4% | M26: ±0.3 | N26: 23,948 | O26: ±3,898 | P26: 5.8% | Q26: ±0.9 | R26: 17,640 | S26: ±3,107 | T26: 7.3% | U26: ±1.3 | V26: 6,308 | W26: ±1,837 | X26: 3.6% | Y26: ±1.0 | Z26: 7,136 | AA26: ±2,022 | AB26: 2.8% | AC26: ±0.8 | AD26: 4,394 | AE26: ±1,226 | AF26: 3.9% | AG26: ±1.1 | AH26: 2,742 | AI26: ±1,454 | AJ26: 2.0% | AK26: ±1.0 | AL26: 48,865 | AM26: ±3,794 | AN26: 6.8% | AO26: ±0.5 | AP26: 39,220 | AQ26: ±3,418 | AR26: 8.7% | AS26: ±0.7 | AT26: 9,645 | AU26: ±1,635 | AV26: 3.6% | AW26: ±0.6
A27: $3,000 or more | B27: 4,609 | C27: ±1,109 | D27: 5.2% | E27: ±1.3 | F27: 3,810 | G27: ±974 | H27: 8.0% | I27: ±2.0 | J27: 799 | K27: ±532 | L27: 1.9% | M27: ±1.3 | N27: 26,545 | O27: ±3,447 | P27: 6.4% | Q27: ±0.8 | R27: 24,404 | S27: ±3,279 | T27: 10.2% | U27: ±1.3 | V27: 2,141 | W27: ±1,230 | X27: 1.2% | Y27: ±0.7 | Z27: 10,565 | AA27: ±1,924 | AB27: 4.2% | AC27: ±0.8 | AD27: 8,667 | AE27: ±1,678 | AF27: 7.8% | AG27: ±1.5 | AH27: 1,898 | AI27: ±929 | AJ27: 1.4% | AK27: ±0.7 | AL27: 63,057 | AM27: ±3,740 | AN27: 8.8% | AO27: ±0.5 | AP27: 55,918 | AQ27: ±3,299 | AR27: 12.4% | AS27: ±0.7 | AT27: 7,139 | AU27: ±1,563 | AV27: 2.7% | AW27: ±0.6
A28: No cash rent | B28: 950 | C28: ±568 | D28: 1.1% | E28: ±0.6 | F28: (X) | G28: (X) | H28: (X) | I28: (X) | J28: 950 | K28: ±568 | L28: 2.3% | M28: ±1.4 | N28: 4,686 | O28: ±1,384 | P28: 1.1% | Q28: ±0.3 | R28: (X) | S28: (X) | T28: (X) | U28: (X) | V28: 4,686 | W28: ±1,384 | X28: 2.7% | Y28: ±0.8 | Z28: 5,434 | AA28: ±1,664 | AB28: 2.2% | AC28: ±0.7 | AD28: (X) | AE28: (X) | AF28: (X) | AG28: (X) | AH28: 5,434 | AI28: ±1,664 | AJ28: 3.9% | AK28: ±1.2 | AL28: 8,227 | AM28: ±1,875 | AN28: 1.1% | AO28: ±0.3 | AP28: (X) | AQ28: (X) | AR28: (X) | AS28: (X) | AT28: 8,227 | AU28: ±1,875 | AV28: 3.1% | AW28: ±0.7
A29: Median (dollars) | B29: 1,152 | C29: ±34 | D29: 1,152 | E29: ±34 | F29: 1,189 | G29: ±89 | H29: 1,189 | I29: ±89 | J29: 1,136 | K29: ±42 | L29: 1,136 | M29: ±42 | N29: 1,514 | O29: ±26 | P29: 1,514 | Q29: ±26 | R29: 1,450 | S29: ±47 | T29: 1,450 | U29: ±47 | V29: 1,568 | W29: ±41 | X29: 1,568 | Y29: ±41 | Z29: 1,201 | AA29: ±28 | AB29: 1,201 | AC29: ±28 | AD29: 1,058 | AE29: ±53 | AF29: 1,058 | AG29: ±53 | AH29: 1,263 | AI29: ±31 | AJ29: 1,263 | AK29: ±31 | AL29: 1,602 | AM29: ±21 | AN29: 1,602 | AO29: ±21 | AP29: 1,663 | AQ29: ±35 | AR29: 1,663 | AS29: ±35 | AT29: 1,556 | AU29: ±28 | AV29: 1,556 | AW29: ±28
A30: MONTHLY HOUSING COSTS AS A PERCENTAGE OF HOUSEHOLD INCOME IN THE PAST 12 MONTHS
A31: Less than $20,000 | B31: 8,433 | C31: ±2,152 | D31: 9.5% | E31: ±2.3 | F31: 3,481 | G31: ±1,278 | H31: 7.4% | I31: ±2.5 | J31: 4,952 | K31: ±1,445 | L31: 12.0% | M31: ±3.5 | N31: 42,117 | O31: ±4,057 | P31: 10.2% | Q31: ±1.0 | R31: 17,140 | S31: ±2,470 | T31: 7.1% | U31: ±1.0 | V31: 24,977 | W31: ±3,520 | X31: 14.4% | Y31: ±2.0 | Z31: 40,856 | AA31: ±3,863 | AB31: 16.3% | AC31: ±1.5 | AD31: 13,012 | AE31: ±2,220 | AF31: 11.6% | AG31: ±1.9 | AH31: 27,844 | AI31: ±3,387 | AJ31: 20.0% | AK31: ±2.4 | AL31: 56,461 | AM31: ±3,683 | AN31: 7.9% | AO31: ±0.5 | AP31: 19,575 | AQ31: ±2,159 | AR31: 4.3% | AS31: ±0.5 | AT31: 36,886 | AU31: ±3,448 | AV31: 13.8% | AW31: ±1.2
A32: Less than 20 percent | B32: 101 | C32: ±143 | D32: 0.1% | E32: ±0.2 | F32: 76 | G32: ±136 | H32: 0.2% | I32: ±0.3 | J32: 25 | K32: ±42 | L32: 0.1% | M32: ±0.1 | N32: 1,271 | O32: ±498 | P32: 0.3% | Q32: ±0.1 | R32: 1,077 | S32: ±473 | T32: 0.4% | U32: ±0.2 | V32: 194 | W32: ±260 | X32: 0.1% | Y32: ±0.2 | Z32: 594 | AA32: ±380 | AB32: 0.2% | AC32: ±0.2 | AD32: 435 | AE32: ±287 | AF32: 0.4% | AG32: ±0.3 | AH32: 159 | AI32: ±266 | AJ32: 0.1% | AK32: ±0.2 | AL32: 1,091 | AM32: ±492 | AN32: 0.2% | AO32: ±0.1 | AP32: 363 | AQ32: ±221 | AR32: 0.1% | AS32: ±0.1 | AT32: 728 | AU32: ±469 | AV32: 0.3% | AW32: ±0.2
A33: 20 to 29 percent | B33: 708 | C33: ±555 | D33: 0.8% | E33: ±0.6 | F33: 77 | G33: ±94 | H33: 0.2% | I33: ±0.2 | J33: 631 | K33: ±527 | L33: 1.5% | M33: ±1.3 | N33: 2,910 | O33: ±1,119 | P33: 0.7% | Q33: ±0.3 | R33: 647 | S33: ±363 | T33: 0.3% | U33: ±0.2 | V33: 2,263 | W33: ±1,041 | X33: 1.3% | Y33: ±0.6 | Z33: 1,930 | AA33: ±951 | AB33: 0.8% | AC33: ±0.4 | AD33: 510 | AE33: ±323 | AF33: 0.5% | AG33: ±0.3 | AH33: 1,420 | AI33: ±874 | AJ33: 1.0% | AK33: ±0.6 | AL33: 4,030 | AM33: ±1,244 | AN33: 0.6% | AO33: ±0.2 | AP33: 928 | AQ33: ±394 | AR33: 0.2% | AS33: ±0.1 | AT33: 3,102 | AU33: ±1,103 | AV33: 1.2% | AW33: ±0.4
A34: 30 percent or more | B34: 7,624 | C34: ±2,127 | D34: 8.6% | E34: ±2.3 | F34: 3,328 | G34: ±1,264 | H34: 7.0% | I34: ±2.5 | J34: 4,296 | K34: ±1,470 | L34: 10.4% | M34: ±3.7 | N34: 37,936 | O34: ±4,051 | P34: 9.2% | Q34: ±1.0 | R34: 15,416 | S34: ±2,434 | T34: 6.4% | U34: ±1.0 | V34: 22,520 | W34: ±3,625 | X34: 13.0% | Y34: ±2.0 | Z34: 38,332 | AA34: ±3,625 | AB34: 15.3% | AC34: ±1.4 | AD34: 12,067 | AE34: ±2,122 | AF34: 10.8% | AG34: ±1.8 | AH34: 26,265 | AI34: ±3,064 | AJ34: 18.9% | AK34: ±2.2 | AL34: 51,340 | AM34: ±3,707 | AN34: 7.2% | AO34: ±0.5 | AP34: 18,284 | AQ34: ±2,040 | AR34: 4.1% | AS34: ±0.5 | AT34: 33,056 | AU34: ±3,408 | AV34: 12.4% | AW34: ±1.2
A35: $20,000 to $34,999 | B35: 10,665 | C35: ±2,586 | D35: 12.0% | E35: ±2.9 | F35: 3,302 | G35: ±1,052 | H35: 7.0% | I35: ±2.2 | J35: 7,363 | K35: ±2,239 | L35: 17.8% | M35: ±5.2 | N35: 41,046 | O35: ±4,383 | P35: 9.9% | Q35: ±1.0 | R35: 16,254 | S35: ±1,982 | T35: 6.8% | U35: ±0.8 | V35: 24,792 | W35: ±3,932 | X35: 14.3% | Y35: ±2.1 | Z35: 34,172 | AA35: ±3,248 | AB35: 13.6% | AC35: ±1.3 | AD35: 11,355 | AE35: ±1,953 | AF35: 10.2% | AG35: ±1.7 | AH35: 22,817 | AI35: ±2,875 | AJ35: 16.4% | AK35: ±2.1 | AL35: 65,033 | AM35: ±5,272 | AN35: 9.1% | AO35: ±0.7 | AP35: 27,901 | AQ35: ±2,782 | AR35: 6.2% | AS35: ±0.6 | AT35: 37,132 | AU35: ±3,943 | AV35: 13.9% | AW35: ±1.5
A36: Less than 20 percent | B36: 995 | C36: ±543 | D36: 1.1% | E36: ±0.6 | F36: 995 | G36: ±543 | H36: 2.1% | I36: ±1.2 | J36: 0 | K36: ±213 | L36: 0.0% | M36: ±0.5 | N36: 4,622 | O36: ±1,076 | P36: 1.1% | Q36: ±0.3 | R36: 4,006 | S36: ±989 | T36: 1.7% | U36: ±0.4 | V36: 616 | W36: ±405 | X36: 0.4% | Y36: ±0.2 | Z36: 3,363 | AA36: ±1,047 | AB36: 1.3% | AC36: ±0.4 | AD36: 2,381 | AE36: ±891 | AF36: 2.1% | AG36: ±0.8 | AH36: 982 | AI36: ±693 | AJ36: 0.7% | AK36: ±0.5 | AL36: 6,321 | AM36: ±1,734 | AN36: 0.9% | AO36: ±0.2 | AP36: 4,834 | AQ36: ±1,413 | AR36: 1.1% | AS36: ±0.3 | AT36: 1,487 | AU36: ±863 | AV36: 0.6% | AW36: ±0.3
A37: 20 to 29 percent | B37: 930 | C37: ±781 | D37: 1.0% | E37: ±0.9 | F37: 770 | G37: ±780 | H37: 1.6% | I37: ±1.6 | J37: 160 | K37: ±162 | L37: 0.4% | M37: ±0.4 | N37: 3,481 | O37: ±1,006 | P37: 0.8% | Q37: ±0.2 | R37: 2,641 | S37: ±780 | T37: 1.1% | U37: ±0.3 | V37: 840 | W37: ±605 | X37: 0.5% | Y37: ±0.3 | Z37: 4,577 | AA37: ±1,381 | AB37: 1.8% | AC37: ±0.6 | AD37: 3,029 | AE37: ±1,141 | AF37: 2.7% | AG37: ±1.0 | AH37: 1,548 | AI37: ±838 | AJ37: 1.1% | AK37: ±0.6 | AL37: 7,472 | AM37: ±1,715 | AN37: 1.0% | AO37: ±0.2 | AP37: 5,562 | AQ37: ±1,439 | AR37: 1.2% | AS37: ±0.3 | AT37: 1,910 | AU37: ±862 | AV37: 0.7% | AW37: ±0.3
A38: 30 percent or more | B38: 8,740 | C38: ±2,447 | D38: 9.8% | E38: ±2.7 | F38: 1,537 | G38: ±907 | H38: 3.2% | I38: ±1.9 | J38: 7,203 | K38: ±2,242 | L38: 17.4% | M38: ±5.2 | N38: 32,943 | O38: ±4,093 | P38: 8.0% | Q38: ±0.9 | R38: 9,607 | S38: ±1,822 | T38: 4.0% | U38: ±0.8 | V38: 23,336 | W38: ±3,657 | X38: 13.5% | Y38: ±2.0 | Z38: 26,232 | AA38: ±3,092 | AB38: 10.5% | AC38: ±1.3 | AD38: 5,945 | AE38: ±1,333 | AF38: 5.3% | AG38: ±1.2 | AH38: 20,287 | AI38: ±2,744 | AJ38: 14.6% | AK38: ±2.0 | AL38: 51,240 | AM38: ±4,488 | AN38: 7.1% | AO38: ±0.6 | AP38: 17,505 | AQ38: ±1,963 | AR38: 3.9% | AS38: ±0.4 | AT38: 33,735 | AU38: ±3,880 | AV38: 12.7% | AW38: ±1.5
A39: $35,000 to $49,999 | B39: 11,768 | C39: ±2,304 | D39: 13.3% | E39: ±2.6 | F39: 4,258 | G39: ±1,100 | H39: 9.0% | I39: ±2.2 | J39: 7,510 | K39: ±2,304 | L39: 18.1% | M39: ±5.3 | N39: 43,267 | O39: ±4,602 | P39: 10.5% | Q39: ±1.1 | R39: 18,001 | S39: ±2,372 | T39: 7.5% | U39: ±1.0 | V39: 25,266 | W39: ±3,924 | X39: 14.6% | Y39: ±2.2 | Z39: 34,150 | AA39: ±3,808 | AB39: 13.6% | AC39: ±1.5 | AD39: 12,436 | AE39: ±2,045 | AF39: 11.1% | AG39: ±1.8 | AH39: 21,714 | AI39: ±3,539 | AJ39: 15.6% | AK39: ±2.4 | AL39: 67,412 | AM39: ±4,847 | AN39: 9.4% | AO39: ±0.7 | AP39: 31,939 | AQ39: ±3,034 | AR39: 7.1% | AS39: ±0.6 | AT39: 35,473 | AU39: ±4,373 | AV39: 13.3% | AW39: ±1.6
A40: Less than 20 percent | B40: 2,037 | C40: ±704 | D40: 2.3% | E40: ±0.8 | F40: 1,662 | G40: ±658 | H40: 3.5% | I40: ±1.4 | J40: 375 | K40: ±326 | L40: 0.9% | M40: ±0.8 | N40: 8,354 | O40: ±1,420 | P40: 2.0% | Q40: ±0.3 | R40: 7,011 | S40: ±1,237 | T40: 2.9% | U40: ±0.5 | V40: 1,343 | W40: ±973 | X40: 0.8% | Y40: ±0.6 | Z40: 5,418 | AA40: ±1,381 | AB40: 2.2% | AC40: ±0.6 | AD40: 5,105 | AE40: ±1,344 | AF40: 4.6% | AG40: ±1.2 | AH40: 313 | AI40: ±260 | AJ40: 0.2% | AK40: ±0.2 | AL40: 12,302 | AM40: ±1,937 | AN40: 1.7% | AO40: ±0.3 | AP40: 10,793 | AQ40: ±1,724 | AR40: 2.4% | AS40: ±0.4 | AT40: 1,509 | AU40: ±740 | AV40: 0.6% | AW40: ±0.3
...

Sheet Income (2020)
B1: Little Rock city, Arkansas | N1: Jacksonville city, Florida | Z1: Memphis city, Tennessee | AL1: Virginia Beach-Norfolk-Newport News, VA-NC Metro Area
B2: Occupied housing units | D2: Percent occupied housing units | F2: Owner-occupied housing units | H2: Percent owner-occupied housing units | J2: Renter-occupied housing units | L2: Percent renter-occupied housing units | N2: Occupied housing units | P2: Percent occupied housing units | R2: Owner-occupied housing units | T2: Percent owner-occupied housing units | V2: Renter-occupied housing units | X2: Percent renter-occupied housing units | Z2: Occupied housing units | AB2: Percent occupied housing units | AD2: Owner-occupied housing units | AF2: Percent owner-occupied housing units | AH2: Renter-occupied housing units | AJ2: Percent renter-occupied housing units | AL2: Occupied housing units | AN2: Percent occupied housing units | AP2: Owner-occupied housing units | AR2: Percent owner-occupied housing units | AT2: Renter-occupied housing units | AV2: Percent renter-occupied housing units
A3: Label | B3: Estimate | C3: Margin of Error | D3: Estimate | E3: Margin of Error | F3: Estimate | G3: Margin of Error | H3: Estimate | I3: Margin of Error | J3: Estimate | K3: Margin of Error | L3: Estimate | M3: Margin of Error | N3: Estimate | O3: Margin of Error | P3: Estimate | Q3: Margin of Error | R3: Estimate | S3: Margin of Error | T3: Estimate | U3: Margin of Error | V3: Estimate | W3: Margin of Error | X3: Estimate | Y3: Margin of Error | Z3: Estimate | AA3: Margin of Error | AB3: Estimate | AC3: Margin of Error | AD3: Estimate | AE3: Margin of Error | AF3: Estimate | AG3: Margin of Error | AH3: Estimate | AI3: Margin of Error | AJ3: Estimate | AK3: Margin of Error | AL3: Estimate | AM3: Margin of Error | AN3: Estimate | AO3: Margin of Error | AP3: Estimate | AQ3: Margin of Error | AR3: Estimate | AS3: Margin of Error | AT3: Estimate | AU3: Margin of Error | AV3: Estimate | AW3: Margin of Error
A4: Occupied housing units | B4: 83,525 | C4: ±1,328 | D4: 83,525 | E4: ±1,328 | F4: 45,625 | G4: ±1,464 | H4: 45,625 | I4: ±1,464 | J4: 37,900 | K4: ±1,341 | L4: 37,900 | M4: ±1,341 | N4: 348,809 | O4: ±2,342 | P4: 348,809 | Q4: ±2,342 | R4: 196,649 | S4: ±2,556 | T4: 196,649 | U4: ±2,556 | V4: 152,160 | W4: ±2,801 | X4: 152,160 | Y4: ±2,801 | Z4: 255,756 | AA4: ±2,087 | AB4: 255,756 | AC4: ±2,087 | AD4: 118,235 | AE4: ±2,383 | AF4: 118,235 | AG4: ±2,383 | AH4: 137,521 | AI4: ±2,353 | AJ4: 137,521 | AK4: ±2,353 | AL4: 672,053 | AM4: ±2,310 | AN4: 672,053 | AO4: ±2,310 | AP4: 418,960 | AQ4: ±3,643 | AR4: 418,960 | AS4: ±3,643 | AT4: 253,093 | AU4: ±3,104 | AV4: 253,093 | AW4: ±3,104
A5: HOUSEHOLD INCOME IN THE PAST 12 MONTHS (IN 2020 INFLATION-ADJUSTED DOLLARS)
A6: Less than $5,000 | B6: 4,065 | C6: ±613 | D6: 4.9% | E6: ±0.7 | F6: 1,187 | G6: ±272 | H6: 2.6% | I6: ±0.6 | J6: 2,878 | K6: ±565 | L6: 7.6% | M6: ±1.5 | N6: 14,463 | O6: ±1,175 | P6: 4.1% | Q6: ±0.3 | R6: 5,082 | S6: ±743 | T6: 2.6% | U6: ±0.4 | V6: 9,381 | W6: ±1,109 | X6: 6.2% | Y6: ±0.7 | Z6: 16,117 | AA6: ±1,123 | AB6: 6.3% | AC6: ±0.4 | AD6: 3,359 | AE6: ±514 | AF6: 2.8% | AG6: ±0.4 | AH6: 12,758 | AI6: ±901 | AJ6: 9.3% | AK6: ±0.6 | AL6: 19,340 | AM6: ±1,315 | AN6: 2.9% | AO6: ±0.2 | AP6: 5,702 | AQ6: ±586 | AR6: 1.4% | AS6: ±0.1 | AT6: 13,638 | AU6: ±961 | AV6: 5.4% | AW6: ±0.4
A7: $5,000 to $9,999 | B7: 2,654 | C7: ±358 | D7: 3.2% | E7: ±0.4 | F7: 600 | G7: ±176 | H7: 1.3% | I7: ±0.4 | J7: 2,054 | K7: ±357 | L7: 5.4% | M7: ±0.9 | N7: 9,964 | O7: ±867 | P7: 2.9% | Q7: ±0.2 | R7: 3,198 | S7: ±650 | T7: 1.6% | U7: ±0.3 | V7: 6,766 | W7: ±783 | X7: 4.4% | Y7: ±0.5 | Z7: 11,396 | AA7: ±725 | AB7: 4.5% | AC7: ±0.3 | AD7: 2,401 | AE7: ±429 | AF7: 2.0% | AG7: ±0.4 | AH7: 8,995 | AI7: ±627 | AJ7: 6.5% | AK7: ±0.5 | AL7: 15,483 | AM7: ±996 | AN7: 2.3% | AO7: ±0.1 | AP7: 3,790 | AQ7: ±425 | AR7: 0.9% | AS7: ±0.1 | AT7: 11,693 | AU7: ±952 | AV7: 4.6% | AW7: ±0.4
A8: $10,000 to $14,999 | B8: 3,213 | C8: ±493 | D8: 3.8% | E8: ±0.6 | F8: 953 | G8: ±199 | H8: 2.1% | I8: ±0.4 | J8: 2,260 | K8: ±431 | L8: 6.0% | M8: ±1.1 | N8: 14,106 | O8: ±1,090 | P8: 4.0% | Q8: ±0.3 | R8: 6,073 | S8: ±686 | T8: 3.1% | U8: ±0.3 | V8: 8,033 | W8: ±729 | X8: 5.3% | Y8: ±0.5 | Z8: 18,866 | AA8: ±1,076 | AB8: 7.4% | AC8: ±0.4 | AD8: 5,729 | AE8: ±780 | AF8: 4.8% | AG8: ±0.6 | AH8: 13,137 | AI8: ±889 | AJ8: 9.6% | AK8: ±0.6 | AL8: 20,210 | AM8: ±996 | AN8: 3.0% | AO8: ±0.1 | AP8: 6,854 | AQ8: ±609 | AR8: 1.6% | AS8: ±0.1 | AT8: 13,356 | AU8: ±805 | AV8: 5.3% | AW8: ±0.3
A9: $15,000 to $19,999 | B9: 3,797 | C9: ±644 | D9: 4.5% | E9: ±0.8 | F9: 1,552 | G9: ±365 | H9: 3.4% | I9: ±0.8 | J9: 2,245 | K9: ±462 | L9: 5.9% | M9: ±1.3 | N9: 14,397 | O9: ±1,123 | P9: 4.1% | Q9: ±0.3 | R9: 5,283 | S9: ±553 | T9: 2.7% | U9: ±0.3 | V9: 9,114 | W9: ±993 | X9: 6.0% | Y9: ±0.7 | Z9: 16,543 | AA9: ±1,128 | AB9: 6.5% | AC9: ±0.4 | AD9: 5,202 | AE9: ±589 | AF9: 4.4% | AG9: ±0.5 | AH9: 11,341 | AI9: ±907 | AJ9: 8.2% | AK9: ±0.7 | AL9: 22,662 | AM9: ±1,189 | AN9: 3.4% | AO9: ±0.2 | AP9: 9,566 | AQ9: ±696 | AR9: 2.3% | AS9: ±0.2 | AT9: 13,096 | AU9: ±909 | AV9: 5.2% | AW9: ±0.4
A10: $20,000 to $24,999 | B10: 5,379 | C10: ±935 | D10: 6.4% | E10: ±1.1 | F10: 2,109 | G10: ±537 | H10: 4.6% | I10: ±1.1 | J10: 3,270 | K10: ±722 | L10: 8.6% | M10: ±1.9 | N10: 17,689 | O10: ±1,269 | P10: 5.1% | Q10: ±0.4 | R10: 6,905 | S10: ±710 | T10: 3.5% | U10: ±0.4 | V10: 10,784 | W10: ±1,000 | X10: 7.1% | Y10: ±0.7 | Z10: 16,018 | AA10: ±1,056 | AB10: 6.3% | AC10: ±0.4 | AD10: 5,376 | AE10: ±610 | AF10: 4.5% | AG10: ±0.5 | AH10: 10,642 | AI10: ±952 | AJ10: 7.7% | AK10: ±0.7 | AL10: 26,588 | AM10: ±1,462 | AN10: 4.0% | AO10: ±0.2 | AP10: 10,890 | AQ10: ±908 | AR10: 2.6% | AS10: ±0.2 | AT10: 15,698 | AU10: ±1,050 | AV10: 6.2% | AW10: ±0.4
A11: $25,000 to $34,999 | B11: 8,879 | C11: ±794 | D11: 10.6% | E11: ±0.9 | F11: 3,143 | G11: ±455 | H11: 6.9% | I11: ±0.9 | J11: 5,736 | K11: ±715 | L11: 15.1% | M11: ±1.8 | N11: 34,575 | O11: ±1,693 | P11: 9.9% | Q11: ±0.5 | R11: 14,661 | S11: ±1,206 | T11: 7.5% | U11: ±0.6 | V11: 19,914 | W11: ±1,357 | X11: 13.1% | Y11: ±0.8 | Z11: 30,963 | AA11: ±1,573 | AB11: 12.1% | AC11: ±0.6 | AD11: 10,761 | AE11: ±667 | AF11: 9.1% | AG11: ±0.6 | AH11: 20,202 | AI11: ±1,555 | AJ11: 14.7% | AK11: ±1.1 | AL11: 52,791 | AM11: ±1,755 | AN11: 7.9% | AO11: ±0.3 | AP11: 23,868 | AQ11: ±1,120 | AR11: 5.7% | AS11: ±0.3 | AT11: 28,923 | AU11: ±1,438 | AV11: 11.4% | AW11: ±0.5
A12: $35,000 to $49,999 | B12: 11,342 | C12: ±754 | D12: 13.6% | E12: ±0.9 | F12: 5,007 | G12: ±621 | H12: 11.0% | I12: ±1.3 | J12: 6,335 | K12: ±678 | L12: 16.7% | M12: ±1.7 | N12: 49,994 | O12: ±2,146 | P12: 14.3% | Q12: ±0.6 | R12: 23,030 | S12: ±1,341 | T12: 11.7% | U12: ±0.7 | V12: 26,964 | W12: ±1,712 | X12: 17.7% | Y12: ±1.0 | Z12: 37,262 | AA12: ±1,787 | AB12: 14.6% | AC12: ±0.7 | AD12: 15,874 | AE12: ±1,193 | AF12: 13.4% | AG12: ±1.0 | AH12: 21,388 | AI12: ±1,416 | AJ12: 15.6% | AK12: ±1.0 | AL12: 82,212 | AM12: ±2,018 | AN12: 12.2% | AO12: ±0.3 | AP12: 39,443 | AQ12: ±1,554 | AR12: 9.4% | AS12: ±0.4 | AT12: 42,769 | AU12: ±1,825 | AV12: 16.9% | AW12: ±0.7
A13: $50,000 to $74,999 | B13: 14,467 | C13: ±1,054 | D13: 17.3% | E13: ±1.2 | F13: 8,098 | G13: ±842 | H13: 17.7% | I13: ±1.7 | J13: 6,369 | K13: ±723 | L13: 16.8% | M13: ±1.7 | N13: 67,772 | O13: ±2,013 | P13: 19.4% | Q13: ±0.6 | R13: 37,611 | S13: ±1,600 | T13: 19.1% | U13: ±0.8 | V13: 30,161 | W13: ±1,599 | X13: 19.8% | Y13: ±1.1 | Z13: 42,529 | AA13: ±1,849 | AB13: 16.6% | AC13: ±0.7 | AD13: 21,387 | AE13: ±1,286 | AF13: 18.1% | AG13: ±1.0 | AH13: 21,142 | AI13: ±1,440 | AJ13: 15.4% | AK13: ±1.0 | AL13: 126,118 | AM13: ±2,546 | AN13: 18.8% | AO13: ±0.4 | AP13: 74,259 | AQ13: ±2,008 | AR13: 17.7% | AS13: ±0.4 | AT13: 51,859 | AU13: ±1,683 | AV13: 20.5% | AW13: ±0.6
A14: $75,000 to $99,999 | B14: 9,110 | C14: ±747 | D14: 10.9% | E14: ±0.9 | F14: 5,378 | G14: ±608 | H14: 11.8% | I14: ±1.3 | J14: 3,732 | K14: ±543 | L14: 9.8% | M14: ±1.4 | N14: 45,650 | O14: ±2,362 | P14: 13.1% | Q14: ±0.7 | R14: 29,799 | S14: ±1,739 | T14: 15.2% | U14: ±0.8 | V14: 15,851 | W14: ±1,263 | X14: 10.4% | Y14: ±0.8 | Z14: 24,075 | AA14: ±1,345 | AB14: 9.4% | AC14: ±0.5 | AD14: 15,227 | AE14: ±960 | AF14: 12.9% | AG14: ±0.8 | AH14: 8,848 | AI14: ±963 | AJ14: 6.4% | AK14: ±0.7 | AL14: 94,729 | AM14: ±2,175 | AN14: 14.1% | AO14: ±0.3 | AP14: 67,414 | AQ14: ±1,983 | AR14: 16.1% | AS14: ±0.4 | AT14: 27,315 | AU14: ±1,207 | AV14: 10.8% | AW14: ±0.5
A15: $100,000 to $149,999 | B15: 9,660 | C15: ±762 | D15: 11.6% | E15: ±0.9 | F15: 7,444 | G15: ±644 | H15: 16.3% | I15: ±1.4 | J15: 2,216 | K15: ±492 | L15: 5.8% | M15: ±1.3 | N15: 46,315 | O15: ±1,891 | P15: 13.3% | Q15: ±0.5 | R15: 35,457 | S15: ±1,738 | T15: 18.0% | U15: ±0.9 | V15: 10,858 | W15: ±921 | X15: 7.1% | Y15: ±0.6 | Z15: 23,296 | AA15: ±1,341 | AB15: 9.1% | AC15: ±0.5 | AD15: 16,833 | AE15: ±1,137 | AF15: 14.2% | AG15: ±0.9 | AH15: 6,463 | AI15: ±758 | AJ15: 4.7% | AK15: ±0.5 | AL15: 118,835 | AM15: ±2,588 | AN15: 17.7% | AO15: ±0.4 | AP15: 94,467 | AQ15: ±2,611 | AR15: 22.5% | AS15: ±0.6 | AT15: 24,368 | AU15: ±1,318 | AV15: 9.6% | AW15: ±0.5
A16: $150,000 or more | B16: 10,959 | C16: ±662 | D16: 13.1% | E16: ±0.8 | F16: 10,154 | G16: ±654 | H16: 22.3% | I16: ±1.4 | J16: 805 | K16: ±232 | L16: 2.1% | M16: ±0.6 | N16: 33,884 | O16: ±1,492 | P16: 9.7% | Q16: ±0.4 | R16: 29,550 | S16: ±1,526 | T16: 15.0% | U16: ±0.8 | V16: 4,334 | W16: ±616 | X16: 2.8% | Y16: ±0.4 | Z16: 18,691 | AA16: ±1,076 | AB16: 7.3% | AC16: ±0.4 | AD16: 16,086 | AE16: ±977 | AF16: 13.6% | AG16: ±0.8 | AH16: 2,605 | AI16: ±387 | AJ16: 1.9% | AK16: ±0.3 | AL16: 93,085 | AM16: ±2,285 | AN16: 13.9% | AO16: ±0.3 | AP16: 82,707 | AQ16: ±2,222 | AR16: 19.7% | AS16: ±0.5 | AT16: 10,378 | AU16: ±808 | AV16: 4.1% | AW16: ±0.3
A17: Median household income (dollars) | B17: 53,620 | C17: ±1,752 | D17: 53,620 | E17: ±1,752 | F17: 75,948 | G17: ±4,356 | H17: 75,948 | I17: ±4,356 | J17: 36,166 | K17: ±2,083 | L17: 36,166 | M17: ±2,083 | N17: 55,531 | O17: ±989 | P17: 55,531 | Q17: ±989 | R17: 72,322 | S17: ±1,341 | T17: 72,322 | U17: ±1,341 | V17: 41,010 | W17: ±979 | X17: 41,010 | Y17: ±979 | Z17: 41,864 | AA17: ±733 | AB17: 41,864 | AC17: ±733 | AD17: 60,976 | AE17: ±1,836 | AF17: 60,976 | AG17: ±1,836 | AH17: 30,973 | AI17: ±662 | AJ17: 30,973 | AK17: ±662 | AL17: 68,454 | AM17: ±753 | AN17: 68,454 | AO17: ±753 | AP17: 87,425 | AQ17: ±945 | AR17: 87,425 | AS17: ±945 | AT17: 45,242 | AU17: ±633 | AV17: 45,242 | AW17: ±633
A18: MONTHLY HOUSING COSTS
A19: Less than $300 | B19: 4,065 | C19: ±514 | D19: 4.9% | E19: ±0.6 | F19: 2,752 | G19: ±443 | H19: 6.0% | I19: ±1.0 | J19: 1,313 | K19: ±281 | L19: 3.5% | M19: ±0.7 | N19: 20,080 | O19: ±1,257 | P19: 5.8% | Q19: ±0.4 | R19: 15,094 | S19: ±1,081 | T19: 7.7% | U19: ±0.6 | V19: 4,986 | W19: ±535 | X19: 3.3% | Y19: ±0.4 | Z19: 14,220 | AA19: ±1,010 | AB19: 5.6% | AC19: ±0.4 | AD19: 10,167 | AE19: ±877 | AF19: 8.6% | AG19: ±0.7 | AH19: 4,053 | AI19: ±467 | AJ19: 2.9% | AK19: ±0.3 | AL19: 21,165 | AM19: ±1,050 | AN19: 3.1% | AO19: ±0.2 | AP19: 12,739 | AQ19: ±824 | AR19: 3.0% | AS19: ±0.2 | AT19: 8,426 | AU19: ±666 | AV19: 3.3% | AW19: ±0.3
A20: $300 to $499 | B20: 8,007 | C20: ±875 | D20: 9.6% | E20: ±1.0 | F20: 6,326 | G20: ±800 | H20: 13.9% | I20: ±1.6 | J20: 1,681 | K20: ±342 | L20: 4.4% | M20: ±0.9 | N20: 29,408 | O20: ±1,496 | P20: 8.4% | Q20: ±0.4 | R20: 25,579 | S20: ±1,428 | T20: 13.0% | U20: ±0.7 | V20: 3,829 | W20: ±553 | X20: 2.5% | Y20: ±0.4 | Z20: 24,402 | AA20: ±1,222 | AB20: 9.5% | AC20: ±0.5 | AD20: 18,870 | AE20: ±1,027 | AF20: 16.0% | AG20: ±0.8 | AH20: 5,532 | AI20: ±665 | AJ20: 4.0% | AK20: ±0.5 | AL20: 45,496 | AM20: ±1,534 | AN20: 6.8% | AO20: ±0.2 | AP20: 37,730 | AQ20: ±1,473 | AR20: 9.0% | AS20: ±0.4 | AT20: 7,766 | AU20: ±691 | AV20: 3.1% | AW20: ±0.3
A21: $500 to $799 | B21: 18,931 | C21: ±1,313 | D21: 22.7% | E21: ±1.4 | F21: 8,329 | G21: ±840 | H21: 18.3% | I21: ±1.7 | J21: 10,602 | K21: ±1,013 | L21: 28.0% | M21: ±2.5 | N21: 51,757 | O21: ±1,887 | P21: 14.8% | Q21: ±0.5 | R21: 31,535 | S21: ±1,324 | T21: 16.0% | U21: ±0.6 | V21: 20,222 | W21: ±1,452 | X21: 13.3% | Y21: ±0.9 | Z21: 55,792 | AA21: ±1,810 | AB21: 21.8% | AC21: ±0.7 | AD21: 22,288 | AE21: ±857 | AF21: 18.9% | AG21: ±0.7 | AH21: 33,504 | AI21: ±1,601 | AJ21: 24.4% | AK21: ±1.1 | AL21: 78,527 | AM21: ±2,148 | AN21: 11.7% | AO21: ±0.3 | AP21: 56,995 | AQ21: ±1,891 | AR21: 13.6% | AS21: ±0.4 | AT21: 21,532 | AU21: ±1,238 | AV21: 8.5% | AW21: ±0.5
A22: $800 to $999 | B22: 15,005 | C22: ±1,219 | D22: 18.0% | E22: ±1.4 | F22: 5,390 | G22: ±672 | H22: 11.8% | I22: ±1.4 | J22: 9,615 | K22: ±1,002 | L22: 25.4% | M22: ±2.4 | N22: 49,392 | O22: ±2,051 | P22: 14.2% | Q22: ±0.6 | R22: 19,009 | S22: ±1,167 | T22: 9.7% | U22: ±0.6 | V22: 30,383 | W22: ±1,663 | X22: 20.0% | Y22: ±1.0 | Z22: 52,522 | AA22: ±2,006 | AB22: 20.5% | AC22: ±0.8 | AD22: 14,762 | AE22: ±1,032 | AF22: 12.5% | AG22: ±0.9 | AH22: 37,760 | AI22: ±1,689 | AJ22: 27.5% | AK22: ±1.2 | AL22: 68,984 | AM22: ±2,226 | AN22: 10.3% | AO22: ±0.3 | AP22: 28,791 | AQ22: ±1,334 | AR22: 6.9% | AS22: ±0.3 | AT22: 40,193 | AU22: ±1,587 | AV22: 15.9% | AW22: ±0.6
A23: $1,000 to $1,499 | B23: 21,019 | C23: ±1,107 | D23: 25.2% | E23: ±1.3 | F23: 10,095 | G23: ±709 | H23: 22.1% | I23: ±1.5 | J23: 10,924 | K23: ±1,018 | L23: 28.8% | M23: ±2.3 | N23: 111,751 | O23: ±2,721 | P23: 32.0% | Q23: ±0.7 | R23: 48,092 | S23: ±2,059 | T23: 24.5% | U23: ±1.0 | V23: 63,659 | W23: ±2,036 | X23: 41.8% | Y23: ±1.2 | Z23: 70,538 | AA23: ±2,303 | AB23: 27.6% | AC23: ±0.9 | AD23: 28,433 | AE23: ±1,510 | AF23: 24.0% | AG23: ±1.1 | AH23: 42,105 | AI23: ±2,137 | AJ23: 30.6% | AK23: ±1.4 | AL23: 190,566 | AM23: ±2,783 | AN23: 28.4% | AO23: ±0.4 | AP23: 87,966 | AQ23: ±2,220 | AR23: 21.0% | AS23: ±0.5 | AT23: 102,600 | AU23: ±2,040 | AV23: 40.5% | AW23: ±0.8
A24: $1,500 to $1,999 | B24: 7,076 | C24: ±555 | D24: 8.5% | E24: ±0.7 | F24: 5,375 | G24: ±513 | H24: 11.8% | I24: ±1.1 | J24: 1,701 | K24: ±376 | L24: 4.5% | M24: ±1.0 | N24: 50,213 | O24: ±2,151 | P24: 14.4% | Q24: ±0.6 | R24: 31,473 | S24: ±1,722 | T24: 16.0% | U24: ±0.8 | V24: 18,740 | W24: ±1,618 | X24: 12.3% | Y24: ±1.0 | Z24: 19,607 | AA24: ±974 | AB24: 7.7% | AC24: ±0.4 | AD24: 11,821 | AE24: ±802 | AF24: 10.0% | AG24: ±0.6 | AH24: 7,786 | AI24: ±768 | AJ24: 5.7% | AK24: ±0.6 | AL24: 135,134 | AM24: ±2,324 | AN24: 20.1% | AO24: ±0.3 | AP24: 89,252 | AQ24: ±2,254 | AR24: 21.3% | AS24: ±0.5 | AT24: 45,882 | AU24: ±1,839 | AV24: 18.1% | AW24: ±0.6
A25: $2,000 to $2,499 | B25: 3,545 | C25: ±506 | D25: 4.2% | E25: ±0.6 | F25: 3,143 | G25: ±469 | H25: 6.9% | I25: ±1.0 | J25: 402 | K25: ±135 | L25: 1.1% | M25: ±0.4 | N25: 16,968 | O25: ±1,303 | P25: 4.9% | Q25: ±0.4 | R25: 13,190 | S25: ±1,061 | T25: 6.7% | U25: ±0.5 | V25: 3,778 | W25: ±599 | X25: 2.5% | Y25: ±0.4 | Z25: 6,667 | AA25: ±790 | AB25: 2.6% | AC25: ±0.3 | AD25: 5,493 | AE25: ±834 | AF25: 4.6% | AG25: ±0.7 | AH25: 1,174 | AI25: ±338 | AJ25: 0.9% | AK25: ±0.2 | AL25: 65,500 | AM25: ±2,004 | AN25: 9.7% | AO25: ±0.3 | AP25: 53,411 | AQ25: ±1,752 | AR25: 12.7% | AS25: ±0.4 | AT25: 12,089 | AU25: ±855 | AV25: 4.8% | AW25: ±0.3
A26: $2,500 to $2,999 | B26: 2,083 | C26: ±328 | D26: 2.5% | E26: ±0.4 | F26: 1,856 | G26: ±311 | H26: 4.1% | I26: ±0.7 | J26: 227 | K26: ±102 | L26: 0.6% | M26: ±0.3 | N26: 6,634 | O26: ±675 | P26: 1.9% | Q26: ±0.2 | R26: 6,181 | S26: ±681 | T26: 3.1% | U26: ±0.3 | V26: 453 | W26: ±191 | X26: 0.3% | Y26: ±0.1 | Z26: 2,711 | AA26: ±406 | AB26: 1.1% | AC26: ±0.2 | AD26: 2,449 | AE26: ±387 | AF26: 2.1% | AG26: ±0.3 | AH26: 262 | AI26: ±103 | AJ26: 0.2% | AK26: ±0.1 | AL26: 30,752 | AM26: ±1,363 | AN26: 4.6% | AO26: ±0.2 | AP26: 27,197 | AQ26: ±1,289 | AR26: 6.5% | AS26: ±0.3 | AT26: 3,555 | AU26: ±533 | AV26: 1.4% | AW26: ±0.2
A27: $3,000 or more | B27: 2,593 | C27: ±440 | D27: 3.1% | E27: ±0.5 | F27: 2,359 | G27: ±421 | H27: 5.2% | I27: ±0.9 | J27: 234 | K27: ±101 | L27: 0.6% | M27: ±0.3 | N27: 7,119 | O27: ±710 | P27: 2.0% | Q27: ±0.2 | R27: 6,496 | S27: ±666 | T27: 3.3% | U27: ±0.3 | V27: 623 | W27: ±210 | X27: 0.4% | Y27: ±0.1 | Z27: 4,221 | AA27: ±610 | AB27: 1.7% | AC27: ±0.2 | AD27: 3,952 | AE27: ±558 | AF27: 3.3% | AG27: ±0.5 | AH27: 269 | AI27: ±117 | AJ27: 0.2% | AK27: ±0.1 | AL27: 27,363 | AM27: ±1,067 | AN27: 4.1% | AO27: ±0.2 | AP27: 24,879 | AQ27: ±1,094 | AR27: 5.9% | AS27: ±0.3 | AT27: 2,484 | AU27: ±334 | AV27: 1.0% | AW27: ±0.1
A28: No cash rent | B28: 1,201 | C28: ±303 | D28: 1.4% | E28: ±0.4 | F28: (X) | G28: (X) | H28: (X) | I28: (X) | J28: 1,201 | K28: ±303 | L28: 3.2% | M28: ±0.8 | N28: 5,487 | O28: ±941 | P28: 1.6% | Q28: ±0.3 | R28: (X) | S28: (X) | T28: (X) | U28: (X) | V28: 5,487 | W28: ±941 | X28: 3.6% | Y28: ±0.6 | Z28: 5,076 | AA28: ±656 | AB28: 2.0% | AC28: ±0.3 | AD28: (X) | AE28: (X) | AF28: (X) | AG28: (X) | AH28: 5,076 | AI28: ±656 | AJ28: 3.7% | AK28: ±0.5 | AL28: 8,566 | AM28: ±623 | AN28: 1.3% | AO28: ±0.1 | AP28: (X) | AQ28: (X) | AR28: (X) | AS28: (X) | AT28: 8,566 | AU28: ±623 | AV28: 3.4% | AW28: ±0.2
A29: Median (dollars) | B29: 930 | C29: ±17 | D29: 930 | E29: ±17 | F29: 1,001 | G29: ±35 | H29: 1,001 | I29: ±35 | J29: 889 | K29: ±17 | L29: 889 | M29: ±17 | N29: 1,082 | O29: ±9 | P29: 1,082 | Q29: ±9 | R29: 1,071 | S29: ±20 | T29: 1,071 | U29: ±20 | V29: 1,089 | W29: ±10 | X29: 1,089 | Y29: ±10 | Z29: 913 | AA29: ±9 | AB29: 913 | AC29: ±9 | AD29: 909 | AE29: ±16 | AF29: 909 | AG29: ±16 | AH29: 915 | AI29: ±10 | AJ29: 915 | AK29: ±10 | AL29: 1,299 | AM29: ±8 | AN29: 1,299 | AO29: ±8 | AP29: 1,423 | AQ29: ±11 | AR29: 1,423 | AS29: ±11 | AT29: 1,187 | AU29: ±8 | AV29: 1,187 | AW29: ±8
A30: MONTHLY HOUSING COSTS AS A PERCENTAGE OF HOUSEHOLD INCOME IN THE PAST 12 MONTHS
A31: Less than $20,000 | B31: 11,208 | C31: ±855 | D31: 13.4% | E31: ±1.0 | F31: 3,767 | G31: ±476 | H31: 8.3% | I31: ±1.0 | J31: 7,441 | K31: ±666 | L31: 19.6% | M31: ±1.7 | N31: 44,235 | O31: ±1,969 | P31: 12.7% | Q31: ±0.6 | R31: 17,331 | S31: ±1,166 | T31: 8.8% | U31: ±0.6 | V31: 26,904 | W31: ±1,612 | X31: 17.7% | Y31: ±1.0 | Z31: 52,646 | AA31: ±1,645 | AB31: 20.6% | AC31: ±0.6 | AD31: 14,999 | AE31: ±1,184 | AF31: 12.7% | AG31: ±0.9 | AH31: 37,647 | AI31: ±1,354 | AJ31: 27.4% | AK31: ±1.0 | AL31: 67,434 | AM31: ±1,867 | AN31: 10.0% | AO31: ±0.3 | AP31: 23,565 | AQ31: ±1,076 | AR31: 5.6% | AS31: ±0.2 | AT31: 43,869 | AU31: ±1,524 | AV31: 17.3% | AW31: ±0.5
A32: Less than 20 percent | B32: 675 | C32: ±276 | D32: 0.8% | E32: ±0.3 | F32: 496 | G32: ±277 | H32: 1.1% | I32: ±0.6 | J32: 179 | K32: ±107 | L32: 0.5% | M32: ±0.3 | N32: 2,574 | O32: ±453 | P32: 0.7% | Q32: ±0.1 | R32: 1,580 | S32: ±335 | T32: 0.8% | U32: ±0.2 | V32: 994 | W32: ±275 | X32: 0.7% | Y32: ±0.2 | Z32: 1,764 | AA32: ±374 | AB32: 0.7% | AC32: ±0.1 | AD32: 1,386 | AE32: ±351 | AF32: 1.2% | AG32: ±0.3 | AH32: 378 | AI32: ±139 | AJ32: 0.3% | AK32: ±0.1 | AL32: 2,835 | AM32: ±394 | AN32: 0.4% | AO32: ±0.1 | AP32: 1,359 | AQ32: ±257 | AR32: 0.3% | AS32: ±0.1 | AT32: 1,476 | AU32: ±286 | AV32: 0.6% | AW32: ±0.1
A33: 20 to 29 percent | B33: 958 | C33: ±224 | D33: 1.1% | E33: ±0.3 | F33: 435 | G33: ±174 | H33: 1.0% | I33: ±0.4 | J33: 523 | K33: ±165 | L33: 1.4% | M33: ±0.4 | N33: 4,689 | O33: ±698 | P33: 1.3% | Q33: ±0.2 | R33: 2,559 | S33: ±525 | T33: 1.3% | U33: ±0.3 | V33: 2,130 | W33: ±461 | X33: 1.4% | Y33: ±0.3 | Z33: 4,170 | AA33: ±485 | AB33: 1.6% | AC33: ±0.2 | AD33: 2,005 | AE33: ±352 | AF33: 1.7% | AG33: ±0.3 | AH33: 2,165 | AI33: ±367 | AJ33: 1.6% | AK33: ±0.3 | AL33: 5,490 | AM33: ±583 | AN33: 0.8% | AO33: ±0.1 | AP33: 2,291 | AQ33: ±320 | AR33: 0.5% | AS33: ±0.1 | AT33: 3,199 | AU33: ±439 | AV33: 1.3% | AW33: ±0.2
A34: 30 percent or more | B34: 9,575 | C34: ±797 | D34: 11.5% | E34: ±0.9 | F34: 2,836 | G34: ±410 | H34: 6.2% | I34: ±0.9 | J34: 6,739 | K34: ±678 | L34: 17.8% | M34: ±1.8 | N34: 36,972 | O34: ±1,783 | P34: 10.6% | Q34: ±0.5 | R34: 13,192 | S34: ±990 | T34: 6.7% | U34: ±0.5 | V34: 23,780 | W34: ±1,524 | X34: 15.6% | Y34: ±1.0 | Z34: 46,712 | AA34: ±1,476 | AB34: 18.3% | AC34: ±0.6 | AD34: 11,608 | AE34: ±989 | AF34: 9.8% | AG34: ±0.8 | AH34: 35,104 | AI34: ±1,365 | AJ34: 25.5% | AK34: ±1.0 | AL34: 59,109 | AM34: ±1,922 | AN34: 8.8% | AO34: ±0.3 | AP34: 19,915 | AQ34: ±1,037 | AR34: 4.8% | AS34: ±0.2 | AT34: 39,194 | AU34: ±1,522 | AV34: 15.5% | AW34: ±0.5
A35: $20,000 to $34,999 | B35: 14,046 | C35: ±1,169 | D35: 16.8% | E35: ±1.3 | F35: 5,252 | G35: ±745 | H35: 11.5% | I35: ±1.5 | J35: 8,794 | K35: ±955 | L35: 23.2% | M35: ±2.4 | N35: 50,924 | O35: ±2,203 | P35: 14.6% | Q35: ±0.6 | R35: 21,566 | S35: ±1,463 | T35: 11.0% | U35: ±0.7 | V35: 29,358 | W35: ±1,790 | X35: 19.3% | Y35: ±1.1 | Z35: 45,924 | AA35: ±1,675 | AB35: 18.0% | AC35: ±0.6 | AD35: 16,137 | AE35: ±923 | AF35: 13.6% | AG35: ±0.8 | AH35: 29,787 | AI35: ±1,805 | AJ35: 21.7% | AK35: ±1.2 | AL35: 77,688 | AM35: ±2,144 | AN35: 11.6% | AO35: ±0.3 | AP35: 34,758 | AQ35: ±1,521 | AR35: 8.3% | AS35: ±0.4 | AT35: 42,930 | AU35: ±1,516 | AV35: 17.0% | AW35: ±0.6
